Workbook

Sheet bom
A1: item_code | B1: item_description | C1: uom | D1: unit_price_$ | E1: unit_wt_kg | F1: category_level1 | G1: category_level2 | H1: category_level3
A2: code1 | B2: item1 | C2: t | D2: 0.26339622 | E2: 1000 | F2: Category1 | G2: Category1 | H2: Category1
A3: code2 | B3: item2 | C3: t | D3: 0.54354911 | E3: 1000 | F3: Category1 | G3: Category1 | H3: Category2
A4: code3 | B4: item3 | C4: p | D4: 0.28799772 | E4: 91 | F4: Category2 | G4: Category2 | H4: Category3
A5: code4 | B5: item4 | C5: t | D5: 0.3194846 | E5: 1000 | F5: Category1 | G5: Category3 | H5: Category4
A6: code5 | B6: item5 | C6: t | D6: 1.0576306 | E6: 1000 | F6: Category1 | G6: Category4 | H6: Category5
A7: code6 | B7: item6 | C7: t | D7: 0.27030584 | E7: 1000 | F7: Category1 | G7: Category5 | H7: Category6
A8: code7 | B8: item7 | C8: t | D8: 0.28381748 | E8: 1000 | F8: Category1 | G8: Category5 | H8: Category7
A9: code8 | B9: item8 | C9: p | D9: 0.33507208 | E9: 1.76 | F9: Category2 | G9: Category6 | H9: Category8
A10: code9 | B10: item9 | C10: p | D10: 0.33386392 | E10: 1.76 | F10: Category2 | G10: Category6 | H10: Category8
A11: code10 | B11: item10 | C11: p | D11: 0.33398474 | E11: 1.76 | F11: Category2 | G11: Category6 | H11: Category8
A12: code11 | B12: item11 | C12: p | D12: 0.33398474 | E12: 1.76 | F12: Category2 | G12: Category6 | H12: Category8
A13: code12 | B13: item12 | C13: p | D13: 0.33398474 | E13: 1.76 | F13: Category2 | G13: Category6 | H13: Category8
... A139: code138 | B139: item138 | C139: p | D139: 0.28408767 | E139: 10.761805 | F139: Category2 | G139: Category8 | H139: Category56

Sheet consumption_figs
A1: item_code | B1: std_cons_rate | C1: std_cons_rate_uom | D1: output_type | E1: production_line
A2: code1 | B2: 0 | C2: k/t | D2: y | E2: a
A3: code2 | B3: 0 | C3: k/t | D3: y | E3: a
A4: code3 | B4: 0 | C4: p/s | D4: y | E4: a
A5: code4 | B5: 34.5 | C5: k/t | D5: y | E5: a
A6: code5 | B6: 0 | C6: k/t | D6: y | E6: a
A7: code6 | B7: 3 | C7: k/t | D7: y | E7: a
A8: code7 | B8: 18 | C8: k/t | D8: y | E8: a
A9: code8 | B9: 0.45454545 | C9: p/s | D9: y | E9: a
A10: code9 | B10: 0.66666667 | C10: p/s | D10: y | E10: a
A11: code10 | B11: 0.26315789 | C11: p/s | D11: y | E11: a
A12: code11 | B12: 0.26315789 | C12: p/s | D12: y | E12: a
A13: code12 | B13: 0.71428571 | C13: p/s | D13: y | E13: a
... A553: code135 | B553: 0 | C553: p/s | D553: x | E553: a

Sheet consumption
A1: date | B1: item_code | C1: cons_qty_base_uom | D1: cons_qty_ton | E1: cons_$ | F1: output_type | G1: production_line | H1: cons_rate | I1: cons_rate_uom
A2: 45658 | B2: code139 | C2: 3.614494 | D2: 3.6746481 | E2: 0.034306662 | F2: C | G2: a
A3: 45658 | B3: code140 | C3: 0.14949401 | D3: 0.11342517 | E3: 0.10788566 | F3: x | G3: a
A4: 45658 | B4: code92 | C4: 0.14891297 | D4: 0.1136468 | E4: 0.1036759 | F4: x | G4: a | H4: =IF(Table2[[#This Row],[cons_rate_uom]]="kg/ton",Table2[[#This Row],[cons_qty_ton]]*1000/SUMIFS(prod!$C:$C,prod!$A:$A,Table2[[#This Row],[date]],prod!$G:$G,Table2[[#This Row],[production_line]],prod!$F:$F,Table2[[#This Row],[output_type]]),IF(Table2[[#This Row],[cons_rate_uom]]="pc/heat",Table2[[#This Row],[cons_qty_base_uom]]/SUMIFS(prod!$E:$E,prod!$A:$A,Table2[[#This Row],[date]],prod!$G:$G,Table2[[#This Row],[production_line]],prod!$F:$F,Table2[[#This Row],[output_type]]),Table2[[#This Row],[cons_qty_ton]]/DAY(EOMONTH(Table2[[#This Row],[date]],0)))) -> 0.003666026 | I4: =IFERROR(INDEX('consumption_figs'!$C:$C,MATCH(Table2[[#This Row],[item_code]],'consumption_figs'!A:A,0),1),"NA") -> p/s
A5: 45658 | B5: code91 | C5: 0.14763096 | D5: 0.11155021 | E5: 0.027242511 | F5: x | G5: a | H5: =IF(Table2[[#This Row],[cons_rate_uom]]="kg/ton",Table2[[#This Row],[cons_qty_ton]]*1000/SUMIFS(prod!$C:$C,prod!$A:$A,Table2[[#This Row],[date]],prod!$G:$G,Table2[[#This Row],[production_line]],prod!$F:$F,Table2[[#This Row],[output_type]]),IF(Table2[[#This Row],[cons_rate_uom]]="pc/heat",Table2[[#This Row],[cons_qty_base_uom]]/SUMIFS(prod!$E:$E,prod!$A:$A,Table2[[#This Row],[date]],prod!$G:$G,Table2[[#This Row],[production_line]],prod!$F:$F,Table2[[#This Row],[output_type]]),Table2[[#This Row],[cons_qty_ton]]/DAY(EOMONTH(Table2[[#This Row],[date]],0)))) -> 0.0035983937 | I5: =IFERROR(INDEX('consumption_figs'!$C:$C,MATCH(Table2[[#This Row],[item_code]],'consumption_figs'!A:A,0),1),"NA") -> k/t
A6: 45658 | B6: code93 | C6: 0.14789805 | D6: 0.111819 | E6: 0.10105672 | F6: x | G6: a | H6: =IF(Table2[[#This Row],[cons_rate_uom]]="kg/ton",Table2[[#This Row],[cons_qty_ton]]*1000/SUMIFS(prod!$C:$C,prod!$A:$A,Table2[[#This Row],[date]],prod!$G:$G,Table2[[#This Row],[production_line]],prod!$F:$F,Table2[[#This Row],[output_type]]),IF(Table2[[#This Row],[cons_rate_uom]]="pc/heat",Table2[[#This Row],[cons_qty_base_uom]]/SUMIFS(prod!$E:$E,prod!$A:$A,Table2[[#This Row],[date]],prod!$G:$G,Table2[[#This Row],[production_line]],prod!$F:$F,Table2[[#This Row],[output_type]]),Table2[[#This Row],[cons_qty_ton]]/DAY(EOMONTH(Table2[[#This Row],[date]],0)))) -> 0.0036070645 | I6: =IFERROR(INDEX('consumption_figs'!$C:$C,MATCH(Table2[[#This Row],[item_code]],'consumption_figs'!A:A,0),1),"NA") -> k/t
A7: 45658 | B7: code94 | C7: 0.13351103 | D7: 0.1136468 | E7: 0.10106209 | F7: x | G7: a | H7: =IF(Table2[[#This Row],[cons_rate_uom]]="kg/ton",Table2[[#This Row],[cons_qty_ton]]*1000/SUMIFS(prod!$C:$C,prod!$A:$A,Table2[[#This Row],[date]],prod!$G:$G,Table2[[#This Row],[production_line]],prod!$F:$F,Table2[[#This Row],[output_type]]),IF(Table2[[#This Row],[cons_rate_uom]]="pc/heat",Table2[[#This Row],[cons_qty_base_uom]]/SUMIFS(prod!$E:$E,prod!$A:$A,Table2[[#This Row],[date]],prod!$G:$G,Table2[[#This Row],[production_line]],prod!$F:$F,Table2[[#This Row],[output_type]]),Table2[[#This Row],[cons_qty_ton]]/DAY(EOMONTH(Table2[[#This Row],[date]],0)))) -> 0.003666026 | I7: =IFERROR(INDEX('consumption_figs'!$C:$C,MATCH(Table2[[#This Row],[item_code]],'consumption_figs'!A:A,0),1),"NA") -> p/s
A8: 45658 | B8: code115 | C8: 0.1365355 | D8: 0.10834158 | E8: 0.093193712 | F8: x | G8: a | H8: =IF(Table2[[#This Row],[cons_rate_uom]]="kg/ton",Table2[[#This Row],[cons_qty_ton]]*1000/SUMIFS(prod!$C:$C,prod!$A:$A,Table2[[#This Row],[date]],prod!$G:$G,Table2[[#This Row],[production_line]],prod!$F:$F,Table2[[#This Row],[output_type]]),IF(Table2[[#This Row],[cons_rate_uom]]="pc/heat",Table2[[#This Row],[cons_qty_base_uom]]/SUMIFS(prod!$E:$E,prod!$A:$A,Table2[[#This Row],[date]],prod!$G:$G,Table2[[#This Row],[production_line]],prod!$F:$F,Table2[[#This Row],[output_type]]),Table2[[#This Row],[cons_qty_ton]]/DAY(EOMONTH(Table2[[#This Row],[date]],0)))) -> 0.0034948896 | I8: =IFERROR(INDEX('consumption_figs'!$C:$C,MATCH(Table2[[#This Row],[item_code]],'consumption_figs'!A:A,0),1),"NA") -> p/s
A9: 45658 | B9: code110 | C9: 0.14923163 | D9: 0.11316112 | E9: 0.10596999 | F9: x | G9: a | H9: =IF(Table2[[#This Row],[cons_rate_uom]]="kg/ton",Table2[[#This Row],[cons_qty_ton]]*1000/SUMIFS(prod!$C:$C,prod!$A:$A,Table2[[#This Row],[date]],prod!$G:$G,Table2[[#This Row],[production_line]],prod!$F:$F,Table2[[#This Row],[output_type]]),IF(Table2[[#This Row],[cons_rate_uom]]="pc/heat",Table2[[#This Row],[cons_qty_base_uom]]/SUMIFS(prod!$E:$E,prod!$A:$A,Table2[[#This Row],[date]],prod!$G:$G,Table2[[#This Row],[production_line]],prod!$F:$F,Table2[[#This Row],[output_type]]),Table2[[#This Row],[cons_qty_ton]]/DAY(EOMONTH(Table2[[#This Row],[date]],0)))) -> 0.0036503585 | I9: =IFERROR(INDEX('consumption_figs'!$C:$C,MATCH(Table2[[#This Row],[item_code]],'consumption_figs'!A:A,0),1),"NA") -> k/t
A10: 45658 | B10: code18 | C10: 0.14960345 | D10: 0.11353532 | E10: 0.10756231 | F10: y | G10: a | H10: =IF(Table2[[#This Row],[cons_rate_uom]]="kg/ton",Table2[[#This Row],[cons_qty_ton]]*1000/SUMIFS(prod!$C:$C,prod!$A:$A,Table2[[#This Row],[date]],prod!$G:$G,Table2[[#This Row],[production_line]],prod!$F:$F,Table2[[#This Row],[output_type]]),IF(Table2[[#This Row],[cons_rate_uom]]="pc/heat",Table2[[#This Row],[cons_qty_base_uom]]/SUMIFS(prod!$E:$E,prod!$A:$A,Table2[[#This Row],[date]],prod!$G:$G,Table2[[#This Row],[production_line]],prod!$F:$F,Table2[[#This Row],[output_type]]),Table2[[#This Row],[cons_qty_ton]]/DAY(EOMONTH(Table2[[#This Row],[date]],0)))) -> 0.0036624296 | I10: =IFERROR(INDEX('consumption_figs'!$C:$C,MATCH(Table2[[#This Row],[item_code]],'consumption_figs'!A:A,0),1),"NA") -> k/t
A11: 45658 | B11: code112 | C11: 0.14503451 | D11: 0.10893713 | E11: 0.099764129 | F11: x | G11: a | H11: =IF(Table2[[#This Row],[cons_rate_uom]]="kg/ton",Table2[[#This Row],[cons_qty_ton]]*1000/SUMIFS(prod!$C:$C,prod!$A:$A,Table2[[#This Row],[date]],prod!$G:$G,Table2[[#This Row],[production_line]],prod!$F:$F,Table2[[#This Row],[output_type]]),IF(Table2[[#This Row],[cons_rate_uom]]="pc/heat",Table2[[#This Row],[cons_qty_base_uom]]/SUMIFS(prod!$E:$E,prod!$A:$A,Table2[[#This Row],[date]],prod!$G:$G,Table2[[#This Row],[production_line]],prod!$F:$F,Table2[[#This Row],[output_type]]),Table2[[#This Row],[cons_qty_ton]]/DAY(EOMONTH(Table2[[#This Row],[date]],0)))) -> 0.0035141011 | I11: =IFERROR(INDEX('consumption_figs'!$C:$C,MATCH(Table2[[#This Row],[item_code]],'consumption_figs'!A:A,0),1),"NA") -> k/t
A12: 45658 | B12: code8 | C12: 0.14576358 | D12: 0.11363965 | E12: 0.10778885 | F12: y | G12: a | H12: =IF(Table2[[#This Row],[cons_rate_uom]]="kg/ton",Table2[[#This Row],[cons_qty_ton]]*1000/SUMIFS(prod!$C:$C,prod!$A:$A,Table2[[#This Row],[date]],prod!$G:$G,Table2[[#This Row],[production_line]],prod!$F:$F,Table2[[#This Row],[output_type]]),IF(Table2[[#This Row],[cons_rate_uom]]="pc/heat",Table2[[#This Row],[cons_qty_base_uom]]/SUMIFS(prod!$E:$E,prod!$A:$A,Table2[[#This Row],[date]],prod!$G:$G,Table2[[#This Row],[production_line]],prod!$F:$F,Table2[[#This Row],[output_type]]),Table2[[#This Row],[cons_qty_ton]]/DAY(EOMONTH(Table2[[#This Row],[date]],0)))) -> 0.0036657951 | I12: =IFERROR(INDEX('consumption_figs'!$C:$C,MATCH(Table2[[#This Row],[item_code]],'consumption_figs'!A:A,0),1),"NA") -> p/s
A13: 45658 | B13: code141 | C13: 0.14927379 | D13: 0.11364601 | E13: 0.1078864 | F13: y | G13: a
A14: 45658 | B14: code10 | C14: 0.14721838 | D14: 0.11364228 | E14: 0.10779503 | F14: y | G14: a | H14: =IF(Table2[[#This Row],[cons_rate_uom]]="kg/ton",Table2[[#This Row],[cons_qty_ton]]*1000/SUMIFS(prod!$C:$C,prod!$A:$A,Table2[[#This Row],[date]],prod!$G:$G,Table2[[#This Row],[production_line]],prod!$F:$F,Table2[[#This Row],[output_type]]),IF(Table2[[#This Row],[cons_rate_uom]]="pc/heat",Table2[[#This Row],[cons_qty_base_uom]]/SUMIFS(prod!$E:$E,prod!$A:$A,Table2[[#This Row],[date]],prod!$G:$G,Table2[[#This Row],[production_line]],prod!$F:$F,Table2[[#This Row],[output_type]]),Table2[[#This Row],[cons_qty_ton]]/DAY(EOMONTH(Table2[[#This Row],[date]],0)))) -> 0.0036658801 | I14: =IFERROR(INDEX('consumption_figs'!$C:$C,MATCH(Table2[[#This Row],[item_code]],'consumption_figs'!A:A,0),1),"NA") -> p/s
A15: 45658 | B15: code11 | C15: 0.14577692 | D15: 0.11363967 | E15: 0.10773045 | F15: y | G15: a | H15: =IF(Table2[[#This Row],[cons_rate_uom]]="kg/ton",Table2[[#This Row],[cons_qty_ton]]*1000/SUMIFS(prod!$C:$C,prod!$A:$A,Table2[[#This Row],[date]],prod!$G:$G,Table2[[#This Row],[production_line]],prod!$F:$F,Table2[[#This Row],[output_type]]),IF(Table2[[#This Row],[cons_rate_uom]]="pc/heat",Table2[[#This Row],[cons_qty_base_uom]]/SUMIFS(prod!$E:$E,prod!$A:$A,Table2[[#This Row],[date]],prod!$G:$G,Table2[[#This Row],[production_line]],prod!$F:$F,Table2[[#This Row],[output_type]]),Table2[[#This Row],[cons_qty_ton]]/DAY(EOMONTH(Table2[[#This Row],[date]],0)))) -> 0.0036657959 | I15: =IFERROR(INDEX('consumption_figs'!$C:$C,MATCH(Table2[[#This Row],[item_code]],'consumption_figs'!A:A,0),1),"NA") -> p/s
A16: 45658 | B16: code12 | C16: 0.1464843 | D16: 0.11364095 | E16: 0.10776214 | F16: y | G16: a | H16: =IF(Table2[[#This Row],[cons_rate_uom]]="kg/ton",Table2[[#This Row],[cons_qty_ton]]*1000/SUMIFS(prod!$C:$C,prod!$A:$A,Table2[[#This Row],[date]],prod!$G:$G,Table2[[#This Row],[production_line]],prod!$F:$F,Table2[[#This Row],[output_type]]),IF(Table2[[#This Row],[cons_rate_uom]]="pc/heat",Table2[[#This Row],[cons_qty_base_uom]]/SUMIFS(prod!$E:$E,prod!$A:$A,Table2[[#This Row],[date]],prod!$G:$G,Table2[[#This Row],[production_line]],prod!$F:$F,Table2[[#This Row],[output_type]]),Table2[[#This Row],[cons_qty_ton]]/DAY(EOMONTH(Table2[[#This Row],[date]],0)))) -> 0.0036658372 | I16: =IFERROR(INDEX('consumption_figs'!$C:$C,MATCH(Table2[[#This Row],[item_code]],'consumption_figs'!A:A,0),1),"NA") -> p/s
A17: 45658 | B17: code13 | C17: 0.14772556 | D17: 0.1136432 | E17: 0.10781446 | F17: y | G17: a | H17: =IF(Table2[[#This Row],[cons_rate_uom]]="kg/ton",Table2[[#This Row],[cons_qty_ton]]*1000/SUMIFS(prod!$C:$C,prod!$A:$A,Table2[[#This Row],[date]],prod!$G:$G,Table2[[#This Row],[production_line]],prod!$F:$F,Table2[[#This Row],[output_type]]),IF(Table2[[#This Row],[cons_rate_uom]]="pc/heat",Table2[[#This Row],[cons_qty_base_uom]]/SUMIFS(prod!$E:$E,prod!$A:$A,Table2[[#This Row],[date]],prod!$G:$G,Table2[[#This Row],[production_line]],prod!$F:$F,Table2[[#This Row],[output_type]]),Table2[[#This Row],[cons_qty_ton]]/DAY(EOMONTH(Table2[[#This Row],[date]],0)))) -> 0.0036659097 | I17: =IFERROR(INDEX('consumption_figs'!$C:$C,MATCH(Table2[[#This Row],[item_code]],'consumption_figs'!A:A,0),1),"NA") -> p/s
A18: 45658 | B18: code9 | C18: 0.14454902 | D18: 0.11363745 | E18: 0.10766685 | F18: y | G18: a | H18: =IF(Table2[[#This Row],[cons_rate_uom]]="kg/ton",Table2[[#This Row],[cons_qty_ton]]*1000/SUMIFS(prod!$C:$C,prod!$A:$A,Table2[[#This Row],[date]],prod!$G:$G,Table2[[#This Row],[production_line]],prod!$F:$F,Table2[[#This Row],[output_type]]),IF(Table2[[#This Row],[cons_rate_uom]]="pc/heat",Table2[[#This Row],[cons_qty_base_uom]]/SUMIFS(prod!$E:$E,prod!$A:$A,Table2[[#This Row],[date]],prod!$G:$G,Table2[[#This Row],[production_line]],prod!$F:$F,Table2[[#This Row],[output_type]]),Table2[[#This Row],[cons_qty_ton]]/DAY(EOMONTH(Table2[[#This Row],[date]],0)))) -> 0.0036657241 | I18: =IFERROR(INDEX('consumption_figs'!$C:$C,MATCH(Table2[[#This Row],[item_code]],'consumption_figs'!A:A,0),1),"NA") -> p/s
A19: 45658 | B19: code14 | C19: 0.14709826 | D19: 0.11364217 | E19: 0.10773148 | F19: y | G19: a | H19: =IF(Table2[[#This Row],[cons_rate_uom]]="kg/ton",Table2[[#This Row],[cons_qty_ton]]*1000/SUMIFS(prod!$C:$C,prod!$A:$A,Table2[[#This Row],[date]],prod!$G:$G,Table2[[#This Row],[production_line]],prod!$F:$F,Table2[[#This Row],[output_type]]),IF(Table2[[#This Row],[cons_rate_uom]]="pc/heat",Table2[[#This Row],[cons_qty_base_uom]]/SUMIFS(prod!$E:$E,prod!$A:$A,Table2[[#This Row],[date]],prod!$G:$G,Table2[[#This Row],[production_line]],prod!$F:$F,Table2[[#This Row],[output_type]]),Table2[[#This Row],[cons_qty_ton]]/DAY(EOMONTH(Table2[[#This Row],[date]],0)))) -> 0.0036658765 | I19: =IFERROR(INDEX('consumption_figs'!$C:$C,MATCH(Table2[[#This Row],[item_code]],'consumption_figs'!A:A,0),1),"NA") -> p/s
A20: 45658 | B20: code20 | C20: 0.14926044 | D20: 0.11326181 | E20: 0.1056202 | F20: y | G20: a | H20: =IF(Table2[[#This Row],[cons_rate_uom]]="kg/ton",Table2[[#This Row],[cons_qty_ton]]*1000/SUMIFS(prod!$C:$C,prod!$A:$A,Table2[[#This Row],[date]],prod!$G:$G,Table2[[#This Row],[production_line]],prod!$F:$F,Table2[[#This Row],[output_type]]),IF(Table2[[#This Row],[cons_rate_uom]]="pc/heat",Table2[[#This Row],[cons_qty_base_uom]]/SUMIFS(prod!$E:$E,prod!$A:$A,Table2[[#This Row],[date]],prod!$G:$G,Table2[[#This Row],[production_line]],prod!$F:$F,Table2[[#This Row],[output_type]]),Table2[[#This Row],[cons_qty_ton]]/DAY(EOMONTH(Table2[[#This Row],[date]],0)))) -> 0.0036536068 | I20: =IFERROR(INDEX('consumption_figs'!$C:$C,MATCH(Table2[[#This Row],[item_code]],'consumption_figs'!A:A,0),1),"NA") -> p/s
A21: 45658 | B21: code3 | C21: 0.14860054 | D21: 0.11354481 | E21: 0.10715346 | F21: x | G21: a | H21: =IF(Table2[[#This Row],[cons_rate_uom]]="kg/ton",Table2[[#This Row],[cons_qty_ton]]*1000/SUMIFS(prod!$C:$C,prod!$A:$A,Table2[[#This Row],[date]],prod!$G:$G,Table2[[#This Row],[production_line]],prod!$F:$F,Table2[[#This Row],[output_type]]),IF(Table2[[#This Row],[cons_rate_uom]]="pc/heat",Table2[[#This Row],[cons_qty_base_uom]]/SUMIFS(prod!$E:$E,prod!$A:$A,Table2[[#This Row],[date]],prod!$G:$G,Table2[[#This Row],[production_line]],prod!$F:$F,Table2[[#This Row],[output_type]]),Table2[[#This Row],[cons_qty_ton]]/DAY(EOMONTH(Table2[[#This Row],[date]],0)))) -> 0.0036627358 | I21: =IFERROR(INDEX('consumption_figs'!$C:$C,MATCH(Table2[[#This Row],[item_code]],'consumption_figs'!A:A,0),1),"NA") -> p/s
A22: 45658 | B22: code69 | C22: 0.1329324 | D22: 0.11286652 | E22: 0.094746261 | F22: x | G22: a | H22: =IF(Table2[[#This Row],[cons_rate_uom]]="kg/ton",Table2[[#This Row],[cons_qty_ton]]*1000/SUMIFS(prod!$C:$C,prod!$A:$A,Table2[[#This Row],[date]],prod!$G:$G,Table2[[#This Row],[production_line]],prod!$F:$F,Table2[[#This Row],[output_type]]),IF(Table2[[#This Row],[cons_rate_uom]]="pc/heat",Table2[[#This Row],[cons_qty_base_uom]]/SUMIFS(prod!$E:$E,prod!$A:$A,Table2[[#This Row],[date]],prod!$G:$G,Table2[[#This Row],[production_line]],prod!$F:$F,Table2[[#This Row],[output_type]]),Table2[[#This Row],[cons_qty_ton]]/DAY(EOMONTH(Table2[[#This Row],[date]],0)))) -> 0.0036408556 | I22: =IFERROR(INDEX('consumption_figs'!$C:$C,MATCH(Table2[[#This Row],[item_code]],'consumption_figs'!A:A,0),1),"NA") -> p/s
A23: 45658 | B23: code70 | C23: 0.14869463 | D23: 0.11361782 | E23: 0.10721927 | F23: y | G23: a | H23: =IF(Table2[[#This Row],[cons_rate_uom]]="kg/ton",Table2[[#This Row],[cons_qty_ton]]*1000/SUMIFS(prod!$C:$C,prod!$A:$A,Table2[[#This Row],[date]],prod!$G:$G,Table2[[#This Row],[production_line]],prod!$F:$F,Table2[[#This Row],[output_type]]),IF(Table2[[#This Row],[cons_rate_uom]]="pc/heat",Table2[[#This Row],[cons_qty_base_uom]]/SUMIFS(prod!$E:$E,prod!$A:$A,Table2[[#This Row],[date]],prod!$G:$G,Table2[[#This Row],[production_line]],prod!$F:$F,Table2[[#This Row],[output_type]]),Table2[[#This Row],[cons_qty_ton]]/DAY(EOMONTH(Table2[[#This Row],[date]],0)))) -> 0.0036650909 | I23: =IFERROR(INDEX('consumption_figs'!$C:$C,MATCH(Table2[[#This Row],[item_code]],'consumption_figs'!A:A,0),1),"NA") -> p/s
A24: 45658 | B24: code101 | C24: 0.037835371 | D24: 0.11364196 | E24: 0.10662406 | F24: x | G24: a | H24: =IF(Table2[[#This Row],[cons_rate_uom]]="kg/ton",Table2[[#This Row],[cons_qty_ton]]*1000/SUMIFS(prod!$C:$C,prod!$A:$A,Table2[[#This Row],[date]],prod!$G:$G,Table2[[#This Row],[production_line]],prod!$F:$F,Table2[[#This Row],[output_type]]),IF(Table2[[#This Row],[cons_rate_uom]]="pc/heat",Table2[[#This Row],[cons_qty_base_uom]]/SUMIFS(prod!$E:$E,prod!$A:$A,Table2[[#This Row],[date]],prod!$G:$G,Table2[[#This Row],[production_line]],prod!$F:$F,Table2[[#This Row],[output_type]]),Table2[[#This Row],[cons_qty_ton]]/DAY(EOMONTH(Table2[[#This Row],[date]],0)))) -> 0.0036658698 | I24: =IFERROR(INDEX('consumption_figs'!$C:$C,MATCH(Table2[[#This Row],[item_code]],'consumption_figs'!A:A,0),1),"NA") -> p/s
A25: 45658 | B25: code104 | C25: 0.13616426 | D25: 0.11338498 | E25: 0.10427215 | F25: x | G25: a | H25: =IF(Table2[[#This Row],[cons_rate_uom]]="kg/ton",Table2[[#This Row],[cons_qty_ton]]*1000/SUMIFS(prod!$C:$C,prod!$A:$A,Table2[[#This Row],[date]],prod!$G:$G,Table2[[#This Row],[production_line]],prod!$F:$F,Table2[[#This Row],[output_type]]),IF(Table2[[#This Row],[cons_rate_uom]]="pc/heat",Table2[[#This Row],[cons_qty_base_uom]]/SUMIFS(prod!$E:$E,prod!$A:$A,Table2[[#This Row],[date]],prod!$G:$G,Table2[[#This Row],[production_line]],prod!$F:$F,Table2[[#This Row],[output_type]]),Table2[[#This Row],[cons_qty_ton]]/DAY(EOMONTH(Table2[[#This Row],[date]],0)))) -> 0.00365758 | I25: =IFERROR(INDEX('consumption_figs'!$C:$C,MATCH(Table2[[#This Row],[item_code]],'consumption_figs'!A:A,0),1),"NA") -> p/s
... A33: 45658 | B33: code106 | C33: 0.14917354 | D33: 0.11310266 | E33: 0.10598027 | F33: x | G33: a | H33: =IF(Table2[[#This Row],[cons_rate_uom]]="kg/ton",Table2[[#This Row],[cons_qty_ton]]*1000/SUMIFS(prod!$C:$C,prod!$A:$A,Table2[[#This Row],[date]],prod!$G:$G,Table2[[#This Row],[production_line]],prod!$F:$F,Table2[[#This Row],[output_type]]),IF(Table2[[#This Row],[cons_rate_uom]]="pc/heat",Table2[[#This Row],[cons_qty_base_uom]]/SUMIFS(prod!$E:$E,prod!$A:$A,Table2[[#This Row],[date]],prod!$G:$G,Table2[[#This Row],[production_line]],prod!$F:$F,Table2[[#This Row],[output_type]]),Table2[[#This Row],[cons_qty_ton]]/DAY(EOMONTH(Table2[[#This Row],[date]],0)))) -> 0.0036484728 | I33: =IFERROR(INDEX('consumption_figs'!$C:$C,MATCH(Table2[[#This Row],[item_code]],'consumption_figs'!A:A,0),1),"NA") -> k/t
A34: 45689 | B34: code139 | C34: 3.0127804 | D34: 3.0690842 | E34: 0.046071752 | F34: C | G34: a
A35: 45689 | B35: code92 | C35: 0.14915323 | D35: 0.1136468 | E35: 0.10494453 | F35: x | G35: a | H35: =IF(Table2[[#This Row],[cons_rate_uom]]="kg/ton",Table2[[#This Row],[cons_qty_ton]]*1000/SUMIFS(prod!$C:$C,prod!$A:$A,Table2[[#This Row],[date]],prod!$G:$G,Table2[[#This Row],[production_line]],prod!$F:$F,Table2[[#This Row],[output_type]]),IF(Table2[[#This Row],[cons_rate_uom]]="pc/heat",Table2[[#This Row],[cons_qty_base_uom]]/SUMIFS(prod!$E:$E,prod!$A:$A,Table2[[#This Row],[date]],prod!$G:$G,Table2[[#This Row],[production_line]],prod!$F:$F,Table2[[#This Row],[output_type]]),Table2[[#This Row],[cons_qty_ton]]/DAY(EOMONTH(Table2[[#This Row],[date]],0)))) -> 0.0040588145 | I35: =IFERROR(INDEX('consumption_figs'!$C:$C,MATCH(Table2[[#This Row],[item_code]],'consumption_figs'!A:A,0),1),"NA") -> p/s
A36: 45689 | B36: code91 | C36: 0.14828364 | D36: 0.11220706 | E36: 0.01509926 | F36: x | G36: a | H36: =IF(Table2[[#This Row],[cons_rate_uom]]="kg/ton",Table2[[#This Row],[cons_qty_ton]]*1000/SUMIFS(prod!$C:$C,prod!$A:$A,Table2[[#This Row],[date]],prod!$G:$G,Table2[[#This Row],[production_line]],prod!$F:$F,Table2[[#This Row],[output_type]]),IF(Table2[[#This Row],[cons_rate_uom]]="pc/heat",Table2[[#This Row],[cons_qty_base_uom]]/SUMIFS(prod!$E:$E,prod!$A:$A,Table2[[#This Row],[date]],prod!$G:$G,Table2[[#This Row],[production_line]],prod!$F:$F,Table2[[#This Row],[output_type]]),Table2[[#This Row],[cons_qty_ton]]/DAY(EOMONTH(Table2[[#This Row],[date]],0)))) -> 0.0040073951 | I36: =IFERROR(INDEX('consumption_figs'!$C:$C,MATCH(Table2[[#This Row],[item_code]],'consumption_figs'!A:A,0),1),"NA") -> k/t
A37: 45689 | B37: code93 | C37: 0.14852031 | D37: 0.11244525 | E37: 0.10340373 | F37: x | G37: a | H37: =IF(Table2[[#This Row],[cons_rate_uom]]="kg/ton",Table2[[#This Row],[cons_qty_ton]]*1000/SUMIFS(prod!$C:$C,prod!$A:$A,Table2[[#This Row],[date]],prod!$G:$G,Table2[[#This Row],[production_line]],prod!$F:$F,Table2[[#This Row],[output_type]]),IF(Table2[[#This Row],[cons_rate_uom]]="pc/heat",Table2[[#This Row],[cons_qty_base_uom]]/SUMIFS(prod!$E:$E,prod!$A:$A,Table2[[#This Row],[date]],prod!$G:$G,Table2[[#This Row],[production_line]],prod!$F:$F,Table2[[#This Row],[output_type]]),Table2[[#This Row],[cons_qty_ton]]/DAY(EOMONTH(Table2[[#This Row],[date]],0)))) -> 0.0040159016 | I37: =IFERROR(INDEX('consumption_figs'!$C:$C,MATCH(Table2[[#This Row],[item_code]],'consumption_figs'!A:A,0),1),"NA") -> k/t
A38: 45689 | B38: code94 | C38: 0.13785774 | D38: 0.1136468 | E38: 0.10289829 | F38: x | G38: a | H38: =IF(Table2[[#This Row],[cons_rate_uom]]="kg/ton",Table2[[#This Row],[cons_qty_ton]]*1000/SUMIFS(prod!$C:$C,prod!$A:$A,Table2[[#This Row],[date]],prod!$G:$G,Table2[[#This Row],[production_line]],prod!$F:$F,Table2[[#This Row],[output_type]]),IF(Table2[[#This Row],[cons_rate_uom]]="pc/heat",Table2[[#This Row],[cons_qty_base_uom]]/SUMIFS(prod!$E:$E,prod!$A:$A,Table2[[#This Row],[date]],prod!$G:$G,Table2[[#This Row],[production_line]],prod!$F:$F,Table2[[#This Row],[output_type]]),Table2[[#This Row],[cons_qty_ton]]/DAY(EOMONTH(Table2[[#This Row],[date]],0)))) -> 0.0040588145 | I38: =IFERROR(INDEX('consumption_figs'!$C:$C,MATCH(Table2[[#This Row],[item_code]],'consumption_figs'!A:A,0),1),"NA") -> p/s
A39: 45689 | B39: code115 | C39: 0.14162106 | D39: 0.11059244 | E39: 0.098871396 | F39: x | G39: a | H39: =IF(Table2[[#This Row],[cons_rate_uom]]="kg/ton",Table2[[#This Row],[cons_qty_ton]]*1000/SUMIFS(prod!$C:$C,prod!$A:$A,Table2[[#This Row],[date]],prod!$G:$G,Table2[[#This Row],[production_line]],prod!$F:$F,Table2[[#This Row],[output_type]]),IF(Table2[[#This Row],[cons_rate_uom]]="pc/heat",Table2[[#This Row],[cons_qty_base_uom]]/SUMIFS(prod!$E:$E,prod!$A:$A,Table2[[#This Row],[date]],prod!$G:$G,Table2[[#This Row],[production_line]],prod!$F:$F,Table2[[#This Row],[output_type]]),Table2[[#This Row],[cons_qty_ton]]/DAY(EOMONTH(Table2[[#This Row],[date]],0)))) -> 0.0039497302 | I39: =IFERROR(INDEX('consumption_figs'!$C:$C,MATCH(Table2[[#This Row],[item_code]],'consumption_figs'!A:A,0),1),"NA") -> p/s
A40: 45689 | B40: code110 | C40: 0.14942106 | D40: 0.11335176 | E40: 0.10673025 | F40: x | G40: a | H40: =IF(Table2[[#This Row],[cons_rate_uom]]="kg/ton",Table2[[#This Row],[cons_qty_ton]]*1000/SUMIFS(prod!$C:$C,prod!$A:$A,Table2[[#This Row],[date]],prod!$G:$G,Table2[[#This Row],[production_line]],prod!$F:$F,Table2[[#This Row],[output_type]]),IF(Table2[[#This Row],[cons_rate_uom]]="pc/heat",Table2[[#This Row],[cons_qty_base_uom]]/SUMIFS(prod!$E:$E,prod!$A:$A,Table2[[#This Row],[date]],prod!$G:$G,Table2[[#This Row],[production_line]],prod!$F:$F,Table2[[#This Row],[output_type]]),Table2[[#This Row],[cons_qty_ton]]/DAY(EOMONTH(Table2[[#This Row],[date]],0)))) -> 0.0040482771 | I40: =IFERROR(INDEX('consumption_figs'!$C:$C,MATCH(Table2[[#This Row],[item_code]],'consumption_figs'!A:A,0),1),"NA") -> k/t
A41: 45689 | B41: code18 | C41: 0.14965678 | D41: 0.11358899 | E41: 0.10772818 | F41: y | G41: a | H41: =IF(Table2[[#This Row],[cons_rate_uom]]="kg/ton",Table2[[#This Row],[cons_qty_ton]]*1000/SUMIFS(prod!$C:$C,prod!$A:$A,Table2[[#This Row],[date]],prod!$G:$G,Table2[[#This Row],[production_line]],prod!$F:$F,Table2[[#This Row],[output_type]]),IF(Table2[[#This Row],[cons_rate_uom]]="pc/heat",Table2[[#This Row],[cons_qty_base_uom]]/SUMIFS(prod!$E:$E,prod!$A:$A,Table2[[#This Row],[date]],prod!$G:$G,Table2[[#This Row],[production_line]],prod!$F:$F,Table2[[#This Row],[output_type]]),Table2[[#This Row],[cons_qty_ton]]/DAY(EOMONTH(Table2[[#This Row],[date]],0)))) -> 0.0040567496 | I41: =IFERROR(INDEX('consumption_figs'!$C:$C,MATCH(Table2[[#This Row],[item_code]],'consumption_figs'!A:A,0),1),"NA") -> k/t
A42: 45689 | B42: code112 | C42: 0.1478974 | D42: 0.11181834 | E42: 0.10474557 | F42: x | G42: a | H42: =IF(Table2[[#This Row],[cons_rate_uom]]="kg/ton",Table2[[#This Row],[cons_qty_ton]]*1000/SUMIFS(prod!$C:$C,prod!$A:$A,Table2[[#This Row],[date]],prod!$G:$G,Table2[[#This Row],[production_line]],prod!$F:$F,Table2[[#This Row],[output_type]]),IF(Table2[[#This Row],[cons_rate_uom]]="pc/heat",Table2[[#This Row],[cons_qty_base_uom]]/SUMIFS(prod!$E:$E,prod!$A:$A,Table2[[#This Row],[date]],prod!$G:$G,Table2[[#This Row],[production_line]],prod!$F:$F,Table2[[#This Row],[output_type]]),Table2[[#This Row],[cons_qty_ton]]/DAY(EOMONTH(Table2[[#This Row],[date]],0)))) -> 0.0039935123 | I42: =IFERROR(INDEX('consumption_figs'!$C:$C,MATCH(Table2[[#This Row],[item_code]],'consumption_figs'!A:A,0),1),"NA") -> k/t
A43: 45689 | B43: code8 | C43: 0.14748328 | D43: 0.11364276 | E43: 0.10784023 | F43: y | G43: a | H43: =IF(Table2[[#This Row],[cons_rate_uom]]="kg/ton",Table2[[#This Row],[cons_qty_ton]]*1000/SUMIFS(prod!$C:$C,prod!$A:$A,Table2[[#This Row],[date]],prod!$G:$G,Table2[[#This Row],[production_line]],prod!$F:$F,Table2[[#This Row],[output_type]]),IF(Table2[[#This Row],[cons_rate_uom]]="pc/heat",Table2[[#This Row],[cons_qty_base_uom]]/SUMIFS(prod!$E:$E,prod!$A:$A,Table2[[#This Row],[date]],prod!$G:$G,Table2[[#This Row],[production_line]],prod!$F:$F,Table2[[#This Row],[output_type]]),Table2[[#This Row],[cons_qty_ton]]/DAY(EOMONTH(Table2[[#This Row],[date]],0)))) -> 0.0040586701 | I43: =IFERROR(INDEX('consumption_figs'!$C:$C,MATCH(Table2[[#This Row],[item_code]],'consumption_figs'!A:A,0),1),"NA") -> p/s
A44: 45689 | B44: code141 | C44: 0.14952273 | D44: 0.11364646 | E44: 0.10789797 | F44: y | G44: a
A45: 45689 | B45: code10 | C45: 0.14841205 | D45: 0.11364445 | E45: 0.10784852 | F45: y | G45: a | H45: =IF(Table2[[#This Row],[cons_rate_uom]]="kg/ton",Table2[[#This Row],[cons_qty_ton]]*1000/SUMIFS(prod!$C:$C,prod!$A:$A,Table2[[#This Row],[date]],prod!$G:$G,Table2[[#This Row],[production_line]],prod!$F:$F,Table2[[#This Row],[output_type]]),IF(Table2[[#This Row],[cons_rate_uom]]="pc/heat",Table2[[#This Row],[cons_qty_base_uom]]/SUMIFS(prod!$E:$E,prod!$A:$A,Table2[[#This Row],[date]],prod!$G:$G,Table2[[#This Row],[production_line]],prod!$F:$F,Table2[[#This Row],[output_type]]),Table2[[#This Row],[cons_qty_ton]]/DAY(EOMONTH(Table2[[#This Row],[date]],0)))) -> 0.0040587302 | I45: =IFERROR(INDEX('consumption_figs'!$C:$C,MATCH(Table2[[#This Row],[item_code]],'consumption_figs'!A:A,0),1),"NA") -> p/s
A46: 45689 | B46: code11 | C46: 0.1481631 | D46: 0.11364399 | E46: 0.10783737 | F46: y | G46: a | H46: =IF(Table2[[#This Row],[cons_rate_uom]]="kg/ton",Table2[[#This Row],[cons_qty_ton]]*1000/SUMIFS(prod!$C:$C,prod!$A:$A,Table2[[#This Row],[date]],prod!$G:$G,Table2[[#This Row],[production_line]],prod!$F:$F,Table2[[#This Row],[output_type]]),IF(Table2[[#This Row],[cons_rate_uom]]="pc/heat",Table2[[#This Row],[cons_qty_base_uom]]/SUMIFS(prod!$E:$E,prod!$A:$A,Table2[[#This Row],[date]],prod!$G:$G,Table2[[#This Row],[production_line]],prod!$F:$F,Table2[[#This Row],[output_type]]),Table2[[#This Row],[cons_qty_ton]]/DAY(EOMONTH(Table2[[#This Row],[date]],0)))) -> 0.0040587141 | I46: =IFERROR(INDEX('consumption_figs'!$C:$C,MATCH(Table2[[#This Row],[item_code]],'consumption_figs'!A:A,0),1),"NA") -> p/s
A47: 45689 | B47: code12 | C47: 0.14774181 | D47: 0.11364323 | E47: 0.10781849 | F47: y | G47: a | H47: =IF(Table2[[#This Row],[cons_rate_uom]]="kg/ton",Table2[[#This Row],[cons_qty_ton]]*1000/SUMIFS(prod!$C:$C,prod!$A:$A,Table2[[#This Row],[date]],prod!$G:$G,Table2[[#This Row],[production_line]],prod!$F:$F,Table2[[#This Row],[output_type]]),IF(Table2[[#This Row],[cons_rate_uom]]="pc/heat",Table2[[#This Row],[cons_qty_base_uom]]/SUMIFS(prod!$E:$E,prod!$A:$A,Table2[[#This Row],[date]],prod!$G:$G,Table2[[#This Row],[production_line]],prod!$F:$F,Table2[[#This Row],[output_type]]),Table2[[#This Row],[cons_qty_ton]]/DAY(EOMONTH(Table2[[#This Row],[date]],0)))) -> 0.0040586868 | I47: =IFERROR(INDEX('consumption_figs'!$C:$C,MATCH(Table2[[#This Row],[item_code]],'consumption_figs'!A:A,0),1),"NA") -> p/s
...

Sheet prod
A1: date | B1: production_uom1 | C1: production_qty1 | D1: production_uom2 | E1: production_qty2 | F1: output_type | G1: production_line | H1: production_type
A2: 45292 | B2: t | C2: 7.3327277 | D2: s | E2: 7.4054962 | F2: x | G2: a | H2: actual
A3: 45323 | B3: t | C3: 4.1340146 | D3: s | E3: 4.2072531 | F3: x | G3: a | H3: actual
A4: 45352 | B4: t | C4: 5.8318773 | D4: s | E4: 5.8883809 | F4: x | G4: a | H4: actual
A5: 45383 | B5: t | C5: 6.3962685 | D5: s | E5: 6.4897599 | F5: x | G5: a | H5: actual
A6: 45413 | B6: t | C6: 6.3184907 | D6: s | E6: 6.4487568 | F6: x | G6: a | H6: actual
A7: 45444 | B7: t | C7: 5.9842324 | D7: s | E7: 6.0933965 | F7: x | G7: a | H7: actual
A8: 45474 | B8: t | C8: 6.7244237 | D8: s | E8: 6.8177849 | F8: x | G8: a | H8: actual
A9: 45505 | B9: t | C9: 6.0432542 | D9: s | E9: 6.0797288 | F9: x | G9: a | H9: actual
A10: 45536 | B10: t | C10: 6.222999 | D10: s | E10: 6.2574089 | F10: x | G10: a | H10: actual
A11: 45566 | B11: t | C11: 6.3323344 | D11: s | E11: 6.5034276 | F11: x | G11: a | H11: actual
A12: 45597 | B12: t | C12: 4.1011917 | D12: s | E12: 4.16625 | F12: x | G12: a | H12: actual
A13: 45627 | B13: t | C13: 0.99432331 | D13: s | E13: 1.0090099 | F13: x | G13: a | H13: actual
... A2317: 46752 | B2317: t | C2317: 0.28302138 | D2317: s | E2317: 0.2825543 | F2317: x | G2317: b | H2317: plan
